Workbook
Name __FAP383562: #REF!
Name __FAP383562: #REF!
Name __FCP383562: #REF!
Name __FCP383562: #REF!
Name __SK1: #N/A
Name _2L1_: [1]Database!$A$3
Name _2L1_: [2]Database!$A$3
Name _FAP383562: #REF!
Name _FAP383562: #REF!
Name _FCP383562: #REF!
Name _FCP383562: #REF!
Name _Lot1: [3]Database!$A$3
Name _Lot1: [2]Database!$A$3
Name _SK1: #N/A
Name a: '[4]TMK280-02'!#REF!
Name a: '[4]TMK280-02'!#REF!
Name aa: #N/A
Name ActualMonthIE: #REF!
Name ActualMonthIE: #REF!
Name ActualMonthME: #REF!
Name ActualMonthME: #REF!
Name ActualMonthPE: [5]pe!$O$1:$O$65536
Name ActualtimeIE: #REF!
Name ActualtimeIE: #REF!
Name ActualTimeME: #REF!
Name ActualTimeME: #REF!
Name ActualTimePE: [5]pe!$L$1:$L$65536
Name Al_Tab断: #REF!
Name Al_Tab断: #REF!
Name all: [6]Sheet2!$C$2:$F$529
Name already: OFFSET(厚度尺寸链计算!start,,4,)
Name already: OFFSET([0]!start,,4,)
Name ax: #REF!
Name ax: #REF!
Name capacity383562: #REF!
Name capacity383562: #REF!
Name ce: OFFSET(厚度尺寸链计算!start,,6,)
Name ce: OFFSET([0]!start,,6,)
Name ContentsIE: #REF!
Name ContentsIE: #REF!
Name ContentsME: #REF!
Name ContentsME: #REF!
Name ContentsPE: [5]pe!$G$1:$G$65536
Name cost383562: #REF!
Name cost383562: #REF!
Name dataH: #REF!
Name dataH: #REF!
Name Designyt: OFFSET(厚度尺寸链计算!start,,7,)
Name Designyt: OFFSET([0]!start,,7,)
Name DF: [9]model!OPERATION
Name DF: [10]model!OPERATION
Name GB: [1]Database!$A$58
Name GB: [2]Database!$A$58
Name GroupA: [3]Database!$A$58
Name GroupA: [2]Database!$A$58
Name GroupB: [11]Database!$A$58
Name GroupB: [2]Database!$A$58
Name Histogram_Plot_Create: [12]!Histogram_Plot_Create
Name Insp_Date: [13]ISRDATA!$U$7
Name ISR_No.: [13]ISRDATA!$M$1

Sheet 封面
B2: CALB普通商密▲3年
B7: L246N183A-B2验证样-设计制程标准
B10: 共 3 页
D14: 文件编号： | E14: L246N183A-B2样-ZCBZ
D15: 版本： | E15: B2
D16: 实施日期： | E16: 45824
C22: 编制 | D22: 校对 | E22: 审核 | F22: 批准 | G22: 会签

Sheet 填写说明
B2: 填写说明：
B3: 1、 | C3: 根据组织管理程序，制程标准是设计部门向工艺部门传递的关键文件，用以指导样件和产品制造、工艺路线和设备开发、产线建设等；
B4: 2、 | C4: 制程标准应该明确设计、工艺、制造中关系产品性能的参数，工艺部门应根据制程标准，准确转化为工艺路线中准确实施的CP、SOP等文件；
C5: 1）合浆配方中填写主材类型，以便工艺工程师制定化成配方；并备注各组分固含量，不备注默认为100%；
C6: 2）采购件公差与技术协议或入检标准或图纸应保持一致；自制件公差参考以往试制标准，或与工艺工程师协商制定；非一次制造公差，应当根据公式计算确定；
C7: 3）辊压厚度，单位微米，数值因应取整，压实密度应当以辊压厚度取整后数值重新计算填写；
C8: 4）负极片装配反弹和干燥反弹率应当定义范围，并重新计算厚度范围；
C9: 5）总注液量中，备注电芯空隙吸液量，及注液系数；
B10: 3、 | C10: 各项参数的测量方法、位置应当备注，工艺部门应当实现，或者采用可靠方法验证后转化；
B11: 4、 | C11: 应当在“制程关注项”中明确注明样件或生产中的注意事项或重点关注项，工艺部门应当给予重点关注，并将其列入试制总结报告；
B12: 5、 | C12: 根据电池设计结构，选填“模切二分卷绕（方形）”、“切片叠片装配（方形）”、“模切二分卷绕（圆柱）”中一份，并将另两份内容清空隐藏、或删除；
B13: 6、 | C13: 制程标准模板中没有内容输入的项目应当划“/”，需补充项目可以增行插入，并标以浅绿色底纹；
B14: 7、 | C14: 制程标准试制前输入一版，试制结束后应当根据试制总结修正一版，并在修订履历中注明；
B15: 8、 | C15: 制程标准版次从“00”开始，依次排序，不区分项目阶段。

Sheet 修订履历表
F3: 文件编号 | G3: =封面!E14 -> L246N183A-B2样-ZCBZ
F4: 发行版次 | G4: =封面!E15 -> B2
F5: 实施日期 | G5: =封面!E16 -> 45824
C7: 修 订 履 历 表
C8: 发行日期 | D8: 版次 | E8: 修订原因及章节说明 | F8: 修订页次 | G8: 总页
C9: 20240720 | D9: 0 | E9: 初版，产线评估
C10: 20250117 | D10: B1 | E10: 1、面密度调整 a. 正极双面面密度由325.2±4.9变更为310.4±4.7 b. 负极双面面密度由208.3±3.1变更为199.4±3.0 2、辊压厚度调整 a. 正极辊压厚度由104±2变更为100.5±2； b. 负极辊压厚度由134±2变更为129±2 3、切片高度尺寸调整 a. 正极极片高度由103.2±0.3变更为107.2±0.3； b. 负极极片高度由105.5±0.3变更为109.5±0.3； 4、隔膜种类由7+3+2变更为7+1.2+1.2+1+1 5、半电芯厚度由18±0.27mm变更为17.36±0.27mm 6、半电芯重量由1004.5±15变更更为1006±15 7、干燥后电池重量由2259±20变更为2261±20 8、注液比例调整 12、电池厚度由41.7±0.3变更为40.4±0.3 9、电池高度由117.6±0.5（总高）115.1±0.4（肩高）变更为125.5±0.5（总高） 120.0±0.4（肩高） 10、干燥后电池重量变更 干燥后电池重量由2261±20变更为
C11: 20250530 | D11: B2 | E11: 1.面密度调整 a.正极双面面密度由310.4±4.7变更为298.2±4.47 b.负极双面面密度由199.4±3.0变更为192.1±2.88 2.留白区宽度调整 a.正极由29.5±0.5变更为29.5±0.7 b.负极由27.7±0.5变更为27.7±0.7 3.辊压后厚度变化 a.正极厚度由100.5±2变更为97.5±2 b.负极厚度由129±2变更为126±2 4.极片宽度变更 a.正极片宽度由107.2±0.3变更为108.1±0.3 b.负极片宽度由109.5±0.3变更为110.4±0.3 5.极片重量变化 a.正极片重量由8.44±0.16变更为8.13±0.16 b.负极片重量由6.17±0.12变更为6.01±0.12 6.叠片层数变更 a.正极片层数由66变更为68 b.负极片层数由67变更为69 7.叠片前极片厚度变更 a.正极片由101±2.0变更为98±2.0 b.负极片由135±3.5变更为130±4 8.半电芯厚度变更 半电芯厚度由17.36±0.27mm @ 300kgf变更为17.4±0.3mm @ 300kgf 9.半电芯重量变更 半电芯重量由1006±15变更为1005±15 10.干燥后电池重量变更 干燥后电池重量由2261±20变更为2262±20 11.注液量变更 注液量由一注439，二注49变更为一注447，二注49 12.新增化成失液量标准 化成失液量<8g 13.新增保液量标准 保液量>486g

Sheet 合浆涂布辊压一分
C3: =封面!B7 -> L246N183A-B2验证样-设计制程标准 | G3: 文件编号 | H3: =封面!E14 -> L246N183A-B2样-ZCBZ
G4: 发行版次 | H4: =封面!E15 -> B2
G5: 实施日期 | H5: =封面!E16 -> 45824
C6: <合浆、涂布、辊切>
C9: 1、基本参数
C10: 工序 | D10: 内容 | E10: 单位 | F10: 正 极 | G10: 负 极 | H10: 备注
C11: 合浆 | D11: 极耳胶合浆配方 | E11: / | F11: 勃姆石BMS-05/HSV900=83/17 | G11: /
D12: 涂炭合浆配方 | E12: / | F12: / | G12: /
D13: 合浆配方 | E13: 代号
E14: 具体比例 | F14: C750B / PVDF5130 / 108-43 / SP = 97.8 / 1.1 / 0.6 / 0.5 | G14: 上层：PA21-E / CMC2300 / LA134D / B1601 / SP =97.2 / 0.6 / 0.8 / 0.8 / 0.6 下层：PA21 / CMC2300 /LA134D / B1601 / SP =96.4 / 0.6 / 1.0 / 1.4 / 0.6
E15: 主材类型 | F15: 4.4V-Ni6 | G15: 350石墨
D16: 增塑剂 | E16: 增塑剂种类 | F16: / | G16: NMP
E17: 添加量 | F17: / | G17: 0.004
C18: 涂布 | D18: 集流体厚度 | E18: μm | F18: 12±1 | G18: 4.5（-0.5，+1.5）
D19: 集流体面密度 | E19: g/m2 | F19: 32.4±1.0 （以实测为准） | G19: 40±1.5（以实测为准）
D20: 涂炭单面密度 | E20: g/m2 | F20: / | G20: /
D21: 涂炭双面密度 | E21: g/m2 | F21: / | G21: /
D22: ☆单面面密度 | E22: g/m2 | F22: 149.1±2.3（1.5%） | G22: 单面底层面密度：48.1±1.5 单面面密度：96.1±1.5（1.5%） | H22: 面密度降低
D23: ☆双面面密度 | E23: g/m2 | F23: 298.2±4.5（1.5%） | G23: 双面底层面密度：144.1±2.2 双面面密度：192.1±2.9（1.5%） | H23: 面密度降低
D24: 涂胶区与涂覆区重叠尺寸 | E24: mm | F24: 0~0.5mm | G24: /
D25: 极耳胶涂布宽度L1 | E25: mm | F25: 4.0±1.0mm | G25: /
D26: 涂膜区宽度L2 | E26: mm | F26: 454±0.5mm | G26: 461.6±0.5mm | H26: 不切底
D27: 留白区宽度L3 | E27: mm | F27: 29.5±0.7mm | G27: 27.7±0.7mm
D28: 涂胶区单面厚度 | E28: μm | F28: 10~40 | G28: /
D29: 涂胶区双面厚度 | E29: μm | F29: 20~80 | G29: /
D30: ☆粘附力 | E30: N/m | F30: ＞6 | G30: ＞6 | H30: 建议收严
D31: 涂布后面电阻 | E31: Ω | F31: ＜1.0 | G31: / | H31: 建议收严
D32: 涂布后增塑剂残留量 | E32: ppm | F32: / | G32: ＜800
C33: 辊切 | D33: 压实密度 | E33: g/cm3 | F33: 3.489 | G33: 1.587 | H33: 压实降低
D34: ☆辊压后厚度 | E34: μm | F34: 97.5±2 | G34: 辊压厚度：126±2 | H34: 厚度变化（二次辊压）
D35: 辊压后面电阻 | E35: Ω | F35: ≤3.0 | G35: /
C37: 3、正极涂布示意图：
C39: 留白区L3 | D39: =F27 -> 29.5±0.7mm
C42: 涂膜区L2 | D42: =F26 -> 454±0.5mm
C43: 涂膜宽度需工艺确认
C46: 极耳胶L1 | D46: =F25 -> 4.0±1.0mm | H46: (单条幅 1出二)箔宽: | I46: 513
C47: 留白区L4 | D47: =F27 -> 29.5±0.7mm
C51: 4、负极涂布示意图：
C53: 留白区L3 | D53: =G27 -> 27.7±0.7mm
C56: 涂膜区L2 | D56: =G26 -> 461.6±0.5mm
...

Sheet 正极模切
I7: 28.6±0.5 | L7: 31.1±0.5
H13: 58±0.5
D14: 95.4±0.5 | O14: 92.9±0.5

Sheet 模切二分卷绕（方形）
C3: =封面!B7 -> L246N183A-B2验证样-设计制程标准 | G3: 文件编号 | H3: =封面!E14 -> L246N183A-B2样-ZCBZ
G4: 发行版次 | H4: =封面!E15 -> B2
G5: 实施日期 | H5: =封面!E16 -> 45824
B6: <模切、二分、卷绕、装配>
C9: 1、基本参数
C10: 工序 | D10: 内容 | E10: 单位 | F10: 正 极 | G10: 负 极 | H10: 备注
C11: 模切二分 | D11: 极耳高度 | E11: mm | F11: 28.6±0.5 | G11: 29.1±0.5 | H11: 含极耳胶或带料区
D12: 极耳宽度（根部） | E12: mm | F12: 58±0.5 | G12: 58±0.5
D13: 极片宽度 | E13: mm | F13: 95.4±0.5（含极耳胶2.5 mm） | G13: 95.4±0.5
D14: 极片长度 | E14: mm | F14: 19008.18±3.00 | G14: 19407.14±3.00
D15: ★涂覆区毛刺长度 | E15: μm | F15: ≤30 | G15: ≤30
D16: ★非涂覆区毛刺长度 | E16: μm | F16: ≤30 | G16: ≤30
D17: 模切尺寸 | E17: 极耳类型 | F17: 一层一极耳 | G17: 一层一极耳
E18: 极耳间距 | F18: 见附图及附表
C19: 卷绕/热压/装配 | D19: 半电芯数量 | E19: 个 | F19: 2
D20: 卷绕层数 | E20: / | F20: 104 | G20: 106
D21: 卷针周长 | E21: mm | F21: 331 | H21: 根据极片长度微调
D22: 卷绕前极片厚度 | E22: μm | F22: 80±2 | G22: 105±3 | H22: 负极片反弹5%
D23: 极片重量 | E23: g | F23: 469.1 | G23: 361.3 | H23: 与模切参数匹配
D24: 隔膜种类 | E24: / | F24: 7+3+2+2
D25: 隔膜宽度 | E25: mm | F25: 100.4±0.5
D26: 陶瓷面方向 | E26: / | F26: 对正极
D27: 卷绕头部负极超出正极尺寸 | E27: mm | F27: ≥5
D28: 卷绕尾部负极超出正极尺寸 | E28: mm | F28: ≥5
D29: ★隔膜底部超出负极尺寸 | E29: mm | F29: ≥1
D30: ★隔膜顶部超出负极尺寸 | E30: mm | F30: ≥1
D31: ★隔膜顶部超出极耳胶边缘尺寸 | E31: mm | F31: ≥1
D32: ★负极底部超出正极尺寸 | E32: mm | F32: ≥0.5
D33: ★负极顶部超出正极尺寸 | E33: mm | F33: ≥0.5
D34: 半电芯宽度(热压后) | E34: mm | F34: 190.7±0.5
D35: 半电芯厚度(热压后) | E35: mm | F35: 21.8±0.3
... D39: ★封口后绝缘压降 | E39: MΩ | F39: 200V、200ms @ Vd1=4%,Vd2=8%
C56: 附表(1.68)
C57: 负极尺寸（中心距） | E57: 正极尺寸（中心距）
C58: D1 | D58: 38.921991 | E58: D1 | F58: 111.62199
C59: D2 | D59: 246.61762 | E59: D2 | F59: 91.589794
C60: D3 | D60: 84.891244 | E60: D3 | F60: 240.75138
C61: D4 | D61: 247.19554 | E61: D4 | F61: 92.255673
C62: D5 | D62: 85.557123 | E62: D5 | F62: 241.41726
C63: D6 | D63: 247.86142 | E63: D6 | F63: 92.921552
...

Sheet 切片叠片装配（方形）
C3: =封面!B7 -> L246N183A-B2验证样-设计制程标准 | G3: 文件编号 | H3: =封面!E14 -> L246N183A-B2样-ZCBZ
G4: 发行版次 | H4: =封面!E15 -> B2
G5: 实施日期 | H5: =封面!E16 -> 45824
C6: <切片、叠片、装配>
C9: 1、基本参数
C10: 工序 | D10: 内容 | E10: 单位 | F10: 正 极 | G10: 负 极 | H10: 备注 | K10: 削薄标准 | N10: 削薄标准
C11: 切片 | D11: 极耳宽度 | E11: mm | F11: 108.1±0.3 | G11: 110.4±0.3 | H11: 极片加高0.9 mm | L11: 负极边缘 | M11: 正极中间
D12: 极片宽度 | E12: mm | F12: 108.1±0.3 | G12: 110.4±0.3 | H12: 极片加高0.9 mm | K12: （-2~6）μm | L12: 2mm处 | M12: 0mm处 | N12: （3~8）μm
D13: 涂覆长度 | E13: mm | F13: 227.3±0.5 | G13: 230.8±0.5
D14: 极片总长 | E14: mm | F14: 256.8±0.8 | G14: 258.5±0.8
D15: 极片重量 | E15: g | F15: 8.13±0.16 | G15: 6.01±0.12 | H15: 收集极片重量
D16: ★涂覆区毛刺长度 | E16: μm | F16: ≤30 | G16: ≤30
D17: ★极耳胶区毛刺长度 | E17: μm | F17: ≤20 | G17: ≤20
D18: ★非涂覆区毛刺长度 | E18: μm | F18: ≤70 | G18: ≤70
C19: 叠片/装配 | D19: 半电芯数量 | E19: 个 | F19: 2 | K19: （-2~5）μm | L19: 8mm处 | M19: 6mm处 | N19: （1~5）um
D20: 叠片层数（半电芯） | E20: / | F20: 68 | G20: 69 | H20: 层数增加2层 | M20: 正极边缘1mm | N20: (0-10) μ
D21: 叠片前极片厚度 | E21: μm | F21: 98±2.0 | G21: 130±4 | H21: 负极反弹3%-4% | M21: 正极边缘3mm | N21: (0-6) μ
D22: 隔膜种类 | E22: / | F22: 7+1.2+1.2+1+1
D23: 隔膜宽度 | E23: mm | F23: 235
D24: 耐高温涂层面方向 | E24: / | F24: 双面
D25: ★隔膜底部超出负极尺寸 | E25: mm | F25: 1.25±0.6
D26: ★隔膜顶部超出负极尺寸 | E26: mm | F26: 1.25±0.6
D27: ★负极底部超出正极尺寸 | E27: mm | F27: 1.15±0.6
D28: ★负极顶部超出正极尺寸 | E28: mm | F28: 1.15±0.6
D29: ★隔膜左侧超出负极尺寸 | E29: mm | F29: 2.1±0.8
D30: ★隔膜右侧超出负极尺寸 | E30: mm | F30: 2.1±0.8
D31: ★负极耳侧负极超出正极尺寸 | E31: mm | F31: 2.0±0.8
D32: ★正极耳侧负极超出正极尺寸 | E32: mm | F32: 1.5±0.8
D33: ★极片对齐度 | E33: mm | F33: <0.5mm
D34: 半电芯厚度 | E34: mm | F34: 17.4±0.3mm @ 300kgf | H34: 收集分布，注意电芯是否分层
D35: 半电芯重量 | E35: g | F35: 1005±15 | H35: 收集电池半电芯重量
D36: 电芯厚度 | E36: mm | F36: /
D37: ★热压后绝缘压降 | E37: V | F37: Vd1=4%,Vd2=8% @200V
D38: ★封口后绝缘压降 | E38: V | F38: Vd1=4%,Vd2=8% @200V
D39: ★封口后绝缘阻值 | E39: MΩ | F39: ≥200MΩ @ 500V
H41: 第 2 页

Sheet 模切二分卷绕 (圆柱)
C3: =封面!B7 -> L246N183A-B2验证样-设计制程标准 | G3: 文件编号 | H3: =封面!E14 -> L246N183A-B2样-ZCBZ
G4: 发行版次 | H4: =封面!E15 -> B2
G5: 实施日期 | H5: =封面!E16 -> 45824
B6: <模切、二分、卷绕、装配>
C9: 1、基本参数
C10: 工序 | D10: 内容 | E10: 单位 | F10: 正 极 | G10: 负 极 | H10: 备注
C11: 模切二分 | D11: 极耳高度 | E11: mm | F11: 21.5±0.5 | G11: 22.5±0.5 | H11: 含极耳胶或带料区
D12: 极耳宽度 | E12: mm | F12: 47±0.5 | G12: 47±0.5
D13: 极片宽度 | E13: mm | F13: 82.0±0.5（含极耳胶3 mm） | G13: 82.5±0.5
D14: 极片长度 | E14: mm | F14: 5676.2±5 | G14: 5957.4±5
D15: ★涂覆区毛刺长度 | E15: μm | F15: ≤30 | G15: ≤30
D16: ★非涂覆区毛刺长度 | E16: μm | F16: ≤30 | G16: ≤30
D17: 模切尺寸 | E17: 极耳类型 | F17: 全极耳 | G17: 全极耳
E18: 极耳间距 | F18: 见附图及附表
D19: 卷绕层数 | E19: / | F19: 40
D20: 卷针内径 | E20: mm | F20: 2 | H20: 根据极片长度微调
D21: 卷针外径 | E21: mm | F21: 3
D22: 卷针高度 | E22: mm | F22: 87
D23: 卷绕前极片厚度 | E23: μm | F23: 111±2 | G23: 132±3 | H23: 负极片反弹不大于6%
D24: 极片重量 | E24: g
D25: 隔膜种类 | E25: / | F25: 9+3+2+2
D26: 隔膜宽度 | E26: mm | F26: 87±0.5
D27: 陶瓷面方向 | E27: / | F27: 对正极
D28: 卷绕头部负极超出正极尺寸 | E28: mm | F28: ≥5
D29: 卷绕尾部负极超出正极尺寸 | E29: mm | F29: ≥5
D30: ★隔膜底部超出负极涂层尺寸 | E30: mm | F30: ≥1
D31: ★隔膜顶部超出极耳胶边缘尺寸 | E31: mm | F31: ≥1
D32: ★负极涂层底部超出正极涂层尺寸 | E32: mm | F32: ≥0.8
D33: ★负极涂层顶部超出正极涂层尺寸 | E33: mm | F33: ≥0.8
D34: 电芯卷绕后直径 | E34: mm | F34: 144.9±0.3
D35: 电芯重量 | E35: g | F35: 311.3±5.0
D36: ★封口后绝缘阻值 | E36: MΩ | F36: >10 @ 300V, 5+3s
F38: >10 @ 300V, 5+2s
C53: 附表(1.68)
C54: 负极尺寸（中心距） | E54: 正极尺寸（中心距）
C55: D1 | D55: 239.25655 | E55: D1 | F55: 146.48901
C56: D2 | D56: 266.18188 | E56: D2 | F56: 267.18674
C57: D3 | D57: 268.00781 | E57: D3 | F57: 269.11267
C58: D4 | D58: 269.83374 | E58: D4 | F58: 271.0386
C59: D5 | D59: 271.65967 | E59: D5 | F59: 272.96453
...

Sheet 干燥注液化成定容
C3: =封面!B7 -> L246N183A-B2验证样-设计制程标准 | G3: 文件编号 | H3: =封面!E14 -> L246N183A-B2样-ZCBZ
G4: 发行版次 | H4: =封面!E15 -> B2
G5: 实施日期 | H5: =封面!E16 -> 45824
B6: <干燥、注液、化成、定容>
C9: 1、基本参数
C10: 工序 | D10: 内容 | E10: 单位 | F10: 内容 | G10: 备注
C11: 干燥注液 | D11: ☆电芯水分 | E11: ppm | F11: ≤200 | G11: 混合样
D12: 干燥后电池重量 | E12: g | F12: 2262±20 | G12: 过程收集数据
D13: 电解液型号 | E13: / | F13: NGE034
D14: 一注 | E14: g | F14: / | G14: 根据化成DOE
D15: 电解液型号 | E15: g | F15: NGE033 | G15: 二注电解液
D16: 总注液量 | E16: g | F16: 一次注液: 450±4g 二次注液：49±3g | G16: 二注方案（电解液增加8g） 一注多注3g,抵消液失量，保证电池重量均值
D17: 干燥后增塑剂残留量 | E17: ppm | F17: /
C18: 化成定容 | D18: 化成液失量 | E18: g | F18: ＜8g | G18: 新增液失量标准（二次辊压&电解液增加）数据统计未7月份投料做支撑
D19: 保液量 | E19: g | F19: ＞486g
D20: ☆电池容量 | E20: Ah | F20: 188-195.0 （0.33C容量标准） | G20: 2.5-4.4V，恒流放电容量，25℃ 客户要求容量3%；需考虑分档
D21: ☆电池ACR | E21: mΩ | F21: / | G21: 根据数据分布确定标准
D22: ☆电池DCR | E22: mΩ | F22: / | G22: 根据数据分布确定标准
D23: ★电池K值（风险） | E23: mV/h | F23: ≤0.03 | G23: 参考值，实际以分选结果为准
D24: ☆电池重量 | E24: g | F24: 2770±20 | G24: 收集分布
D25: ☆电池直径（圆柱专用） | E25: mm | F25: /
D26: ☆电池厚度 | E26: mm | F26: 40.4±0.3 | G26: 300kgf压力
D27: ☆电池宽度 | E27: mm | F27: 245.5±0.4 | G27: 最宽处
D28: ☆电池高度 | E28: mm | F28: 122.5±0.5（总高） 120.0±0.4（肩高）
D29: 电池OCV | E29: V | F29: / | G29: 根据数据分布分析
D30: OCV分组极差 | E30: mV | F30: / | G30: 根据数据分布分析
D31: 容量分组极差 | E31: Ah | F31: / | G31: 根据数据分布分析
D32: DCR分组极差 | E32: mΩ | F32: / | G32: 根据数据分布分析
D33: ACR分组极差 | E33: mΩ | F33: / | G33: 根据数据分布分析
D34: 边电压 | E34: V | F34: 2.2-3.2V
D35: 化成后负极片厚度 | E35: μm | F35: / | G35: 检测化成后极片厚度
D36: 定容后极片满电厚度 | E36: μm | F36: / | G36: 检测定容后极片厚度
H38: 第 3 页

Sheet 厚度尺寸链计算
B2: 电池厚度计算表
B4: 极片 | C4: 面密度 | D4: 压实密度 | E4: 极片层数 | F4: 辊压厚度/μm | G4: 极片物理反弹率 | H4: 装配段极片厚度/μm | I4: 70%SOC反弹率 | J4: 70%SOC极片厚度/μm | K4: BOL满电反弹率 | L4: BOL满电极片厚度/μm | M4: EOL满电反弹率 | N4: EOL满电极片厚度/μm
B5: 正极 | C5: =[17]设计总表!G9 -> 310.35141 | D5: =[17]设计总表!I9 -> 3.506 | E5: =[17]设计总表!I5 -> 132 | F5: =C5/D5+O19*1000 -> 100.52008 | G5: =[17]设计总表!C43 -> 0.01 | H5: =(F5-O19*1000)*(1+G5)+O19*1000 -> 101.40528 | I5: =[17]设计总表!C44 -> 0.02 | J5: =(F5-O19*1000)*(1+I5)+O19*1000 -> 102.29049 | K5: =[17]设计总表!C45 -> 0.02 | L5: =(F5-O19*1000)*(1+K5)+O19*1000 -> 102.29049 | M5: =[17]设计总表!C46 -> 0.05 | N5: =(F5-O19*1000)*(1+M5)+O19*1000 -> 104.94609
B6: 公差 | F6: 2 | G6: 0 | H6: =(F5+F6-O19*1000)*(1+G5)+O19*1000-H5 -> 2.02 | I6: 0.01 | J6: =(F5+F6-O19*1000)*(1+I5+I6)+O19*1000-J5 -> 2.9452008 | K6: 0.01 | L6: =(F5+F6-O19*1000)*(1+K5+K6)+O19*1000-L5 -> 2.9452008 | M6: 0.02 | N6: =(F5+F6-O19*1000)*(1+M5+M6)+O19*1000-N5 -> 3.9104017
B7: 负极 | C7: =[17]设计总表!G8 -> 199.43154 | D7: =[17]设计总表!I8 -> 1.608 | E7: =[17]设计总表!I5+[17]设计总表!P5 -> 134 | F7: =C7/D7+N19*1000 -> 129.02459 | G7: =[17]设计总表!C32 -> 0.05 | H7: =(F7-N19*1000)*(1+G7)+N19*1000 -> 135.22582 | I7: =[17]设计总表!C33 -> 0.24 | J7: =(F7-N19*1000)*(1+I7)+N19*1000 -> 158.79049 | K7: =[17]设计总表!C34 -> 0.26 | L7: =(F7-N19*1000)*(1+K7)+N19*1000 -> 161.27099 | M7: =[17]设计总表!C35 -> 0.4 | N7: =(F7-N19*1000)*(1+M7)+N19*1000 -> 178.63443
B8: 公差 | F8: 2 | G8: 0.01 | H8: =(F7+F8-N19*1000)*(1+G8+G7)+N19*1000-H7 -> 3.3602459 | I8: 0.02 | J8: =(F7+F8-N19*1000)*(1+I7+I8)+N19*1000-J7 -> 5.0004918 | K8: 0.02 | L8: =(F7+F8-N19*1000)*(1+K7+K8)+N19*1000-L7 -> 5.0404918 | M8: 0.05 | N8: =(F7+F8-N19*1000)*(1+M7+M8)+N19*1000-N7 -> 9.1012296
B10: 半电芯 | H10: 热压 | J10: 70%SOC | L10: BOL满电态 | N10: EOL满电态
B11: 半电芯厚度/mm | H11: =(H7*E7/L20+H5*E5/L20)/1000+C19*C20/L20+K19*2 -> 17.388379 | J11: =(J7*E7/L20+J5*E5/L20)/1000+E19*E20/L20+K19*2 -> 19.436635 | L11: =(L7*E7/[17]设计总表!P5+L5*E5/[17]设计总表!P5)/1000+E19*E20/[17]设计总表!P5+K19*2 -> 19.602828 | N11: =(N7*E7/[17]设计总表!P5+N5*E5/[17]设计总表!P5)/1000+C19*C20/[17]设计总表!P5+K19*2 -> 20.530448
B12: 公差/mm | H12: =SQRT(SUMSQ(H6*E5/L20,H8*E7/L20))/1000 -> 0.26164987 | J12: =SQRT(SUMSQ(J6*E5/L20,J8*E7/L20))/1000 -> 0.38733955 | L12: =SQRT(SUMSQ(L6*E5/L20,L8*E7/L20))/1000 -> 0.38965997
B14: 电池 | J14: 70%SOC | L14: BOL满电态 | N14: EOL满电态
B15: 电池厚度/mm | J15: =J11*[17]设计总表!P5+F19*F20+G19*G20+H19*H20+J19*J20 -> 40.37327 | L15: =L11*[17]设计总表!P5+F19*F20+G19*G20+H19*H20+J19*J20 -> 40.705656 | N15: =N11*[17]设计总表!P5+F19*F20+G19*G20+H19*H20+J19*J20 -> 42.560897
B16: 公差/mm | J16: =SQRT(SUMSQ(J12+D24,0.15+0.1+0.01)) -> 0.44456653
B18: 基本设计信息 | C18: 隔膜（热压后）厚度 | D18: 隔膜（热压后）厚度公差 | E18: 隔膜(化成后，包含液膜) | F18: 低粘膜 | G18: L型包胶 | H18: 壳体大面壁厚 | I18: 大面壁厚公差 | J18: 蓝膜 | K18: 叠片收尾胶 | L18: JR数量 | M18: 电池厚度 | N18: 铜箔厚度 | O18: 铝箔厚度
B19: 厚度/mm | C19: =[17]设计总表!D15 -> 0.0115 | D19: 0.0001 | E19: =[17]设计总表!D15+[17]设计总表!G15 -> 0.0145 | F19: =[17]设计总表!F39 -> 0.08 | G19: =[17]设计总表!F40 -> 0.03 | H19: =[17]设计总表!F36 -> 0.5 | I19: 0.05 | J19: =[17]设计总表!F38 -> 0.08 | K19: =[17]设计总表!F37 -> 0.03 | M19: =[17]设计总表!B5 -> 40.4 | N19: =[17]设计总表!I15 -> 0.005 | O19: =[17]设计总表!J15 -> 0.012
B20: 层数 | C20: =[17]设计总表!N5*[17]设计总表!P5 -> 274 | E20: =C20 -> 274 | F20: 2 | G20: 6 | H20: 2 | J20: 2 | K20: 2 | L20: =[17]设计总表!P5 -> 2
B22: 设计参数 | C22: 入壳 | D22: 出货（70%SOC） | E22: BOL满电 | F22: EOL满电
B23: 松紧比 | C23: =(H11*L20)/(M19-F19*F20-G19*G20-H19*H20-J19*J20) -> 0.89400405 | D23: =(J11*L20)/(M19-F19*F20-G19*G20-H19*H20-J19*J20) -> 0.99931286 | E23: =(L11*L20)/(M19-F19*F20-G19*G20-H19*H20-J19*J20) -> 1.0078575 | F23: =(N11*L20)/(M19-F19*F20-G19*G20-H19*H20-J19*J20) -> 1.0555501
B24: 超厚/mm | C24: / | D24: =J15-M19 -> -0.026729788 | E24: =L15-M19 -> 0.30565612 | F24: =N15-M19 -> 2.160897
B26: 注：1、壳体侧边刚性较强，不易变形，极耳保护胶、焊印保护胶由于在侧边，与正负极涂覆区域几乎无重叠，且正负极边缘侧有削薄，不计入厚度尺寸链
B27: 2、JR半电芯厚度=正极片厚度*正极片层数+隔膜厚度*隔膜层数+负极片厚度*负极片层数
B28: 3、电池厚度=半电芯厚度*半电芯数量+低粘膜厚度*层数+L型包胶厚度*层数+壳体大面壁厚度*2+蓝膜厚度*层数
B29: 4、半电芯厚度公差计算逻辑：所有正极片/负极片厚度偏差造成的半电芯厚度偏差按照极限公差进行；正极片和负极片厚度偏差之间按照概率公差进行；热压后隔膜厚度偏差波动较小，偏差计算时可以忽略
B30: 5、电池厚度公差计算逻辑：半电芯厚度偏差之间按照概率公差进行；壳体厚度偏差按照极限公差进行
